Workbook

Sheet Cover
B2: NEXFLOW
B3: The First GCC-Native AI-Powered CRM
B5: Pre-Seed Financial Model · 3-Year Projections
B6: $100K raise · Bootstrap team · 18,000 customers by Y3
B9: WORKBOOK CONTENTS
B10: 01 · Assumptions | C10: All model drivers — pricing, growth, costs
B11: 02 · Cost Breakdown | C11: Every expense line itemized in USD
B12: 03 · Revenue Build | C12: Customer cohorts, ARR build
B13: 04 · Unit Economics | C13: CAC · LTV · Payback
B14: 05 · P&L | C14: 3-year income statement
B15: 06 · Cash Flow | C15: Operating cash, burn, runway
B16: 07 · Valuation | C16: Exit scenarios, IRR
B17: 08 · Marketing Plan | C17: Campaign-by-campaign breakdown
B18: 09 · Reliability Stack | C18: Uptime, monitoring, DR
B21: KEY METRICS (Year 3)
B22: Ending Customers (Y3) | D22: ='03 · Revenue Build'!D23 -> 19200
B23: Ending ARR (Y3) | D23: ='03 · Revenue Build'!D22 -> 178329600
B24: Revenue (Y3) | D24: ='05 · P&L'!D5 -> 110656125
B25: Gross Margin (Y3) | D25: ='05 · P&L'!D15 -> 0.81
B26: Net Income (Y3) | D26: ='05 · P&L'!D30 -> 71382769
B27: Y1 Net Income | D27: ='05 · P&L'!B30 -> 982039.6
B28: Pre-seed Raise | D28: ='07 · Valuation'!B4 -> 100000
B29: Investor Ownership | D29: ='07 · Valuation'!B7 -> 0.0625

Sheet 01 · Assumptions
A1: NEXFLOW · MODEL ASSUMPTIONS
A2: GCC-first AI CRM · $100K raise · Freelance team · All blue cells editable
B4: Year 1 (2026) | C4: Year 2 (2027) | D4: Year 3 (2028)
A6: 1. PRICING ($/seat/mo) — below HubSpot & Salesforce
A7: Free tier ($/seat/mo) | B7: 0 | C7: 0 | D7: 0
A8: Starter ($/seat/mo) | B8: 19 | C8: 19 | D8: 19
A9: Professional ($/seat/mo) | B9: 79 | C9: 79 | D9: 79
A10: Business ($/seat/mo) | B10: 129 | C10: 129 | D10: 129
A11: Enterprise T1 300-750 seats ($/seat/mo) | B11: 199 | C11: 199 | D11: 199
A12: Enterprise T2 750-2000 seats ($/seat/mo) | B12: 249 | C12: 249 | D12: 249
A13: Enterprise T3 2000+ seats ($/seat/mo) | B13: 299 | C13: 299 | D13: 299
A14: Mix % · Starter | B14: 0.5 | C14: 0.4 | D14: 0.35
A15: Mix % · Professional | B15: 0.35 | C15: 0.4 | D15: 0.4
A16: Mix % · Business | B16: 0.12 | C16: 0.15 | D16: 0.18
A17: Mix % · Enterprise T1 | B17: 0.02 | C17: 0.03 | D17: 0.04
A18: Mix % · Enterprise T2 | B18: 0.01 | C18: 0.015 | D18: 0.02
A19: Mix % · Enterprise T3 | B19: 0 | C19: 0.005 | D19: 0.01
A20: Blended ARPU ($/seat/mo) | B20: =B8*B14+B9*B15+B10*B16+B11*B17+B12*B18+B13*B19 -> 59.1 | C20: =C8*C14+C9*C15+C10*C16+C11*C17+C12*C18+C13*C19 -> 69.75 | D20: =D8*D14+D9*D15+D10*D16+D11*D17+D12*D18+D13*D19 -> 77.4
A22: 2. CUSTOMER GROWTH — GCC first-mover advantage
A23: New paying customers per year | B23: 1200 | C23: 5000 | D23: 13000
A24: Avg seats per customer | B24: 5 | C24: 7 | D24: 10
A25: Gross logo churn rate (annual) | B25: 0.1 | C25: 0.08 | D25: 0.06
A26: Net revenue retention (NRR) | B26: 1.12 | C26: 1.18 | D26: 1.25
A27: Starting customers (Jan 1) | B27: 0 | C27: 0 | D27: 0
A29: 3. COST OF GOODS SOLD (COGS %)
A30: Cloud & infrastructure (AWS me-south-1) % | B30: 0.07 | C30: 0.06 | D30: 0.05
A31: AI/LLM APIs (Claude, OpenAI TTS) % | B31: 0.08 | C31: 0.07 | D31: 0.06
A32: Twilio voice & SMS % | B32: 0.03 | C32: 0.03 | D32: 0.03
A33: Third-party integrations % | B33: 0.02 | C33: 0.02 | D33: 0.02
A34: Payment processing (Stripe/PayTabs) % | B34: 0.03 | C34: 0.03 | D34: 0.03
A35: Total COGS % | B35: =SUM(B30:B34) -> 0.23 | C35: =SUM(C30:C34) -> 0.21 | D35: =SUM(D30:D34) -> 0.19
A36: Gross Margin % | B36: =1-B35 -> 0.77 | C36: =1-C35 -> 0.79 | D36: =1-D35 -> 0.81
A38: 4. OPERATING EXPENSES ($ absolute, from Cost Breakdown)
A39: Team (freelance + part-time + founder) | B39: 33600 | C39: 72000 | D39: 180000
A40: Infrastructure & APIs + Reliability | B40: 13426 | C40: 35000 | D40: 85000
A41: Marketing campaigns | B41: 6200 | C41: 25000 | D41: 80000
A42: Legal, accounting, compliance | B42: 4100 | C42: 8000 | D42: 18000
A43: Tools, SaaS stack | B43: 2304 | C43: 5000 | D43: 12000
A44: Ops, travel, misc | B44: 900 | C44: 3000 | D44: 8000
A45: Buffer / contingency | B45: 8870 | C45: 12000 | D45: 20000
...

Sheet 02 · Cost Breakdown
A1: YEAR 1 COST BREAKDOWN · EVERY LINE ITEMIZED
A3: LINE ITEM | B3: Monthly $ | C3: Months | D3: Annual $ | E3: Notes
A4: TEAM
A5: Developer 1 (India freelance, part-time) | B5: 800 | C5: 12 | D5: =B5*C5 -> 9600 | E5: Per-project / hourly, $800/mo equiv
A6: Developer 2 (GCC part-time) | B6: 2000 | C6: 12 | D6: =B6*C6 -> 24000 | E6: Part-time contract, executing on existing architecture
A7: Founder / CEO (equity only) | B7: 0 | C7: 12 | D7: =B7*C7 -> 0 | E7: No salary Y1 — founder stake
A8: Subtotal Team | D8: =SUM(D5:D7) -> 33600
A10: INFRASTRUCTURE & APIs + RELIABILITY STACK
A11: AWS me-south-1 primary (EC2, RDS, S3) | B11: 150 | C11: 12 | D11: =B11*C11 -> 1800 | E11: Bahrain region, Multi-AZ
A12: AWS eu-central-1 DR backup | B12: 50 | C12: 12 | D12: =B12*C12 -> 600 | E12: Disaster recovery, Frankfurt
A13: Cloudflare Pro (DDoS, WAF, CDN) | B13: 20 | C13: 12 | D13: =B13*C13 -> 240 | E13: Security + performance
A14: Datadog APM (monitoring) | B14: 100 | C14: 12 | D14: =B14*C14 -> 1200 | E14: Application performance, alerts
A15: Sentry error tracking | B15: 26 | C15: 12 | D15: =B15*C15 -> 312 | E15: Instant exception alerts
A16: PagerDuty on-call alerting | B16: 20 | C16: 12 | D16: =B16*C16 -> 240 | E16: Founder + devs paged instantly
A17: UptimeRobot external checks | B17: 7 | C17: 12 | D17: =B17*C17 -> 84 | E17: Global uptime monitoring
A18: AWS Backup + S3 storage | B18: 30 | C18: 12 | D18: =B18*C18 -> 360 | E18: Daily backups, 35-day retention
A19: Claude API (Haiku 4.5 primary) | B19: 400 | C19: 12 | D19: =B19*C19 -> 4800 | E19: $1/$5 per MTok, mostly Haiku
A20: OpenAI TTS (voice agent) | B20: 150 | C20: 12 | D20: =B20*C20 -> 1800 | E20: $0.015/min audio
A21: Twilio Voice + SMS | B21: 125 | C21: 12 | D21: =B21*C21 -> 1500 | E21: $0.013/min + SMS
A22: Stripe billing fees (0.5%) | B22: 50 | C22: 12 | D22: =B22*C22 -> 600 | E22: Beyond transaction fees in COGS
A23: Domain + SSL (Cloudflare/Let's Encrypt) | B23: 3 | C23: 12 | D23: =B23*C23 -> 36 | E23: nexflow.com
A24: Subtotal Infrastructure | D24: =SUM(D11:D23) -> 13572
A26: MARKETING — lean, GCC-focused, organic-first
A27: LinkedIn MENA targeted ads | B27: 200 | C27: 12 | D27: =B27*C27 -> 2400 | E27: GCC decision-makers
A28: Arabic content writer (1/week) | B28: 150 | C28: 12 | D28: =B28*C28 -> 1800 | E28: 4 articles/month, $37.50 each
A29: Event presence (LEAP or Biban shared) | B29: 125 | C29: 12 | D29: =B29*C29 -> 1500 | E29: One GCC event Y1, booth share
A30: Referral program rewards | B30: 42 | C30: 12 | D30: =B30*C30 -> 504 | E30: Customer-driven growth
A31: LinkedIn personal brand (time, not $) | B31: 0 | C31: 12 | D31: =B31*C31 -> 0 | E31: Founder-led, zero cost
A32: Product Hunt + HackerNews launch | B32: 0 | C32: 12 | D32: =B32*C32 -> 0 | E32: Organic launch, no spend
A33: Subtotal Marketing | D33: =SUM(D27:D32) -> 6204
A35: LEGAL, ACCOUNTING, COMPLIANCE (GCC-based)
A36: Saudi LLC / MISA incorporation | B36: 125 | C36: 12 | D36: =B36*C36 -> 1500 | E36: One-time ~$1,500 annualized
A37: Legal templates + review | B37: 125 | C37: 12 | D37: =B37*C37 -> 1500 | E37: ToS, DPA, Privacy Policy
A38: Trademark SAIP (Saudi) + GCC | B38: 42 | C38: 12 | D38: =B38*C38 -> 504 | E38: One-time $500 annualized
A39: Bookkeeping (part-time) | B39: 50 | C39: 12 | D39: =B39*C39 -> 600 | E39: Monthly reconciliation
A40: Subtotal Legal | D40: =SUM(D36:D39) -> 4104
A42: TOOLS & SOFTWARE
A43: GitHub Teams (3 seats) | B43: 12 | C43: 12 | D43: =B43*C43 -> 144 | E43: Code hosting
A44: Linear (3 seats) | B44: 24 | C44: 12 | D44: =B44*C44 -> 288 | E44: Project management
A45: Slack Pro (3 seats) | B45: 21 | C45: 12 | D45: =B45*C45 -> 252 | E45: Team comms
...

Sheet 03 · Revenue Build
A1: REVENUE BUILD · CUSTOMER COHORTS & ARR
A3: QUARTERLY BUILD
B4: Y1Q1 | C4: Y1Q2 | D4: Y1Q3 | E4: Y1Q4 | F4: Y2Q1 | G4: Y2Q2 | H4: Y2Q3 | I4: Y2Q4 | J4: Y3Q1 | K4: Y3Q2 | L4: Y3Q3 | M4: Y3Q4 | N4: Y3 End
A6: CUSTOMER COUNT
A7: New customers added | B7: 150 | C7: 250 | D7: 350 | E7: 450 | F7: 900 | G7: 1150 | H7: 1400 | I7: 1550 | J7: 2600 | K7: 3100 | L7: 3500 | M7: 3800
A8: Quarterly churn (logo) | B8: 0.026 | C8: 0.026 | D8: 0.026 | E8: 0.026 | F8: 0.021 | G8: 0.021 | H8: 0.021 | I8: 0.021 | J8: 0.015 | K8: 0.015 | L8: 0.015 | M8: 0.015
A9: Customers lost | B9: =ROUND('01 · Assumptions'!B27*B8,0) -> 0 | C9: =ROUND(B11*C8,0) -> 0 | D9: =ROUND(C11*D8,0) -> 0 | E9: =ROUND(D11*E8,0) -> 0 | F9: =ROUND(E11*F8,0) -> 0 | G9: =ROUND(F11*G8,0) -> 0 | H9: =ROUND(G11*H8,0) -> 0 | I9: =ROUND(H11*I8,0) -> 0 | J9: =ROUND(I11*J8,0) -> 0 | ... M9: =ROUND(L11*M8,0) -> 0
A10: Ending customers (quarter) | B10: ='01 · Assumptions'!B27+B7-B9 -> 150 | C10: =B10+C7-C9 -> 400 | D10: =C10+D7-D9 -> 750 | E10: =D10+E7-E9 -> 1200 | F10: =E10+F7-F9 -> 2100 | G10: =F10+G7-G9 -> 3250 | H10: =G10+H7-H9 -> 4650 | I10: =H10+I7-I9 -> 6200 | J10: =I10+J7-J9 -> 8800 | ... M10: =L10+M7-M9 -> 19200 | N10: =M10 -> 19200
A12: SEATS & ARR
A13: Avg seats per customer | B13: 5 | C13: 5 | D13: 5 | E13: 5 | F13: 7 | G13: 7 | H13: 7 | I13: 7 | J13: 10 | K13: 10 | L13: 10 | M13: 10
A14: Total seats | B14: =B10*B13 -> 750 | C14: =C10*C13 -> 2000 | D14: =D10*D13 -> 3750 | E14: =E10*E13 -> 6000 | F14: =F10*F13 -> 14700 | G14: =G10*G13 -> 22750 | H14: =H10*H13 -> 32550 | I14: =I10*I13 -> 43400 | ... M14: =M10*M13 -> 192000
A15: Blended ARPU ($/seat/mo) | B15: ='01 · Assumptions'!B20 -> 59.1 | C15: ='01 · Assumptions'!B20 -> 59.1 | D15: ='01 · Assumptions'!B20 -> 59.1 | E15: ='01 · Assumptions'!B20 -> 59.1 | F15: ='01 · Assumptions'!C20 -> 69.75 | G15: ='01 · Assumptions'!C20 -> 69.75 | H15: ='01 · Assumptions'!C20 -> 69.75 | I15: ='01 · Assumptions'!C20 -> 69.75 | J15: ='01 · Assumptions'!D20 -> 77.4 | K15: ='01 · Assumptions'!D20 -> 77.4 | L15: ='01 · Assumptions'!D20 -> 77.4 | M15: ='01 · Assumptions'!D20 -> 77.4
A16: ARR (end of quarter) | B16: =B14*B15*12 -> 531900 | C16: =C14*C15*12 -> 1418400 | D16: =D14*D15*12 -> 2659500 | E16: =E14*E15*12 -> 4255200 | F16: =F14*F15*12 -> 12303900 | G16: =G14*G15*12 -> 19041750 | H16: =H14*H15*12 -> 27244350 | I16: =I14*I15*12 -> 36325800 | ... M16: =M14*M15*12 -> 178329600
A17: Quarterly Revenue | B17: =B16/4/2 -> 66487.5 | C17: =(B16+C16)/2/4 -> 243787.5 | D17: =(C16+D16)/2/4 -> 509737.5 | E17: =(D16+E16)/2/4 -> 864337.5 | F17: =(E16+F16)/2/4 -> 2069887.5 | G17: =(F16+G16)/2/4 -> 3918206.2 | H17: =(G16+H16)/2/4 -> 5785762.5 | I17: =(H16+I16)/2/4 -> 7946268.8 | J17: =(I16+J16)/2/4 -> 14757525 | ... M17: =(L16+M16)/2/4 -> 40170600
A19: ANNUAL TOTALS
B20: Year 1 | C20: Year 2 | D20: Year 3
A21: Annual Revenue | B21: =SUM(B17:E17) -> 1684350 | C21: =SUM(F17:I17) -> 19720125 | D21: =SUM(J17:M17) -> 110656125
A22: Ending ARR | B22: =E16 -> 4255200 | C22: =I16 -> 36325800 | D22: =M16 -> 178329600
A23: Ending Customers | B23: =E10 -> 1200 | C23: =I10 -> 6200 | D23: =M10 -> 19200

Sheet 04 · Unit Economics
A1: UNIT ECONOMICS
B3: Year 1 | C3: Year 2 | D3: Year 3
A4: ARPA ($/yr) | B4: ='01 · Assumptions'!B20*'01 · Assumptions'!B24*12 -> 3546 | C4: ='01 · Assumptions'!C20*'01 · Assumptions'!C24*12 -> 5859 | D4: ='01 · Assumptions'!D20*'01 · Assumptions'!D24*12 -> 9288
A5: Gross Margin % | B5: ='01 · Assumptions'!B36 -> 0.77 | C5: ='01 · Assumptions'!C36 -> 0.79 | D5: ='01 · Assumptions'!D36 -> 0.81
A6: Gross Profit per Account ($/yr) | B6: =B4*B5 -> 2730.42 | C6: =C4*C5 -> 4628.61 | D6: =D4*D5 -> 7523.28
A7: Annual Churn | B7: ='01 · Assumptions'!B25 -> 0.1 | C7: ='01 · Assumptions'!C25 -> 0.08 | D7: ='01 · Assumptions'!D25 -> 0.06
A8: LTV ($) | B8: =B6/B7 -> 27304.2 | C8: =C6/C7 -> 57857.625 | D8: =D6/D7 -> 125388
A9: CAC ($, blended from marketing spend / new custs) | B9: ='01 · Assumptions'!B41/'01 · Assumptions'!B23 -> 5.1666667 | C9: ='01 · Assumptions'!C41/'01 · Assumptions'!C23 -> 5 | D9: ='01 · Assumptions'!D41/'01 · Assumptions'!D23 -> 6.1538462
A10: CAC Payback (months) | B10: =B9/(B6/12) -> 0.022707129 | C10: =C9/(C6/12) -> 0.012962855 | D10: =D9/(D6/12) -> 0.009815686
A11: LTV : CAC | B11: =B8/B9 -> 5284.6839 | C11: =C8/C9 -> 11571.525 | D11: =D8/D9 -> 20375.55

Sheet 05 · P&L
A1: INCOME STATEMENT (P&L)
A3: $ figures | B3: Year 1 | C3: Year 2 | D3: Year 3
A4: REVENUE
A5: Subscription Revenue | B5: ='03 · Revenue Build'!B21 -> 1684350 | C5: ='03 · Revenue Build'!C21 -> 19720125 | D5: ='03 · Revenue Build'!D21 -> 110656125
A7: COST OF GOODS SOLD
A8: Cloud & Infrastructure | B8: ='01 · Assumptions'!B30*B5 -> 117904.5 | C8: ='01 · Assumptions'!C30*C5 -> 1183207.5 | D8: ='01 · Assumptions'!D30*D5 -> 5532806.2
A9: AI/LLM APIs | B9: ='01 · Assumptions'!B31*B5 -> 134748 | C9: ='01 · Assumptions'!C31*C5 -> 1380408.8 | D9: ='01 · Assumptions'!D31*D5 -> 6639367.5
A10: Twilio Voice & SMS | B10: ='01 · Assumptions'!B32*B5 -> 50530.5 | C10: ='01 · Assumptions'!C32*C5 -> 591603.75 | D10: ='01 · Assumptions'!D32*D5 -> 3319683.8
A11: Third-party Integrations | B11: ='01 · Assumptions'!B33*B5 -> 33687 | C11: ='01 · Assumptions'!C33*C5 -> 394402.5 | D11: ='01 · Assumptions'!D33*D5 -> 2213122.5
A12: Payment Processing | B12: ='01 · Assumptions'!B34*B5 -> 50530.5 | C12: ='01 · Assumptions'!C34*C5 -> 591603.75 | D12: ='01 · Assumptions'!D34*D5 -> 3319683.8
A13: Total COGS | B13: =SUM(B8:B12) -> 387400.5 | C13: =SUM(C8:C12) -> 4141226.2 | D13: =SUM(D8:D12) -> 21024664
A14: GROSS PROFIT | B14: =B5-B13 -> 1296949.5 | C14: =C5-C13 -> 15578899 | D14: =D5-D13 -> 89631461
A15: Gross Margin % | B15: =B14/B5 -> 0.77 | C15: =C14/C5 -> 0.79 | D15: =D14/D5 -> 0.81
A17: OPERATING EXPENSES (from Assumptions)
A18: Team (freelance + founder) | B18: ='01 · Assumptions'!B39 -> 33600 | C18: ='01 · Assumptions'!C39 -> 72000 | D18: ='01 · Assumptions'!D39 -> 180000
A19: Infrastructure & Reliability | B19: ='01 · Assumptions'!B40 -> 13426 | C19: ='01 · Assumptions'!C40 -> 35000 | D19: ='01 · Assumptions'!D40 -> 85000
A20: Marketing | B20: ='01 · Assumptions'!B41 -> 6200 | C20: ='01 · Assumptions'!C41 -> 25000 | D20: ='01 · Assumptions'!D41 -> 80000
A21: Legal & Compliance | B21: ='01 · Assumptions'!B42 -> 4100 | C21: ='01 · Assumptions'!C42 -> 8000 | D21: ='01 · Assumptions'!D42 -> 18000
A22: Tools & Software | B22: ='01 · Assumptions'!B43 -> 2304 | C22: ='01 · Assumptions'!C43 -> 5000 | D22: ='01 · Assumptions'!D43 -> 12000
A23: Operations | B23: ='01 · Assumptions'!B44 -> 900 | C23: ='01 · Assumptions'!C44 -> 3000 | D23: ='01 · Assumptions'!D44 -> 8000
A24: Buffer | B24: ='01 · Assumptions'!B45 -> 8870 | C24: ='01 · Assumptions'!C45 -> 12000 | D24: ='01 · Assumptions'!D45 -> 20000
A25: Total OpEx | B25: =SUM(B18:B24) -> 69400 | C25: =SUM(C18:C24) -> 160000 | D25: =SUM(D18:D24) -> 403000
A26: OPERATING INCOME (EBITDA) | B26: =B14-B25 -> 1227549.5 | C26: =C14-C25 -> 15418899 | D26: =D14-D25 -> 89228461
A27: Operating Margin % | B27: =B26/B5 -> 0.72879716 | C27: =C26/C5 -> 0.78188646 | D27: =D26/D5 -> 0.80635809
A29: Tax @ 20% | B29: =IF(B26>0,B26*'01 · Assumptions'!B49,0) -> 245509.9 | C29: =IF(C26>0,C26*'01 · Assumptions'!C49,0) -> 3083779.8 | D29: =IF(D26>0,D26*'01 · Assumptions'!D49,0) -> 17845692
A30: NET INCOME | B30: =B26-B29 -> 982039.6 | C30: =C26-C29 -> 12335119 | D30: =D26-D29 -> 71382769

Sheet 06 · Cash Flow
A1: CASH FLOW
B3: Year 1 | C3: Year 2 | D3: Year 3
A4: Net Income | B4: ='05 · P&L'!B30 -> 982039.6 | C4: ='05 · P&L'!C30 -> 12335119 | D4: ='05 · P&L'!D30 -> 71382769
A5: Operating Cash Flow (≈ Net Income, SaaS) | B5: =B4 -> 982039.6 | C5: =C4 -> 12335119 | D5: =D4 -> 71382769
A7: Pre-seed raise (Y1) | B7: 100000 | C7: 0 | D7: 0
A8: Beginning cash | B8: 0 | C8: =B9 -> 1082039.6 | D8: =C9 -> 13417159
A9: Ending cash | B9: =B8+B7+B5 -> 1082039.6 | C9: =B9+C7+C5 -> 13417159 | D9: =C9+D7+D5 -> 84799928

Sheet 07 · Valuation
A1: VALUATION · IRR
A3: PRE-SEED DEAL TERMS
A4: Pre-seed Investment | B4: 100000
A5: Pre-money valuation | B5: 1500000
A6: Post-money valuation | B6: =B5+B4 -> 1600000
A7: Investor ownership % | B7: =B4/B6 -> 0.0625
A9: EXIT SCENARIOS (Y3 ARR × Multiple)
B10: Conservative | C10: Base | D10: Upside
A11: Year 3 Ending ARR | B11: ='03 · Revenue Build'!D22 -> 178329600 | C11: ='03 · Revenue Build'!D22 -> 178329600 | D11: ='03 · Revenue Build'!D22 -> 178329600
A12: Revenue multiple | B12: 8 | C12: 12 | D12: 18
A13: Enterprise Value | B13: =B11*B12 -> 1426636800 | C13: =C11*C12 -> 2139955200 | D13: =D11*D12 -> 3209932800
A14: Investor share | B14: =B13*B7 -> 89164800 | C14: =C13*B7 -> 133747200 | D14: =D13*B7 -> 200620800
A15: MOIC | B15: =B14/B4 -> 891.648 | C15: =C14/B4 -> 1337.472 | D15: =D14/B4 -> 2006.208
A16: IRR (3-yr hold) | B16: =(B14/B4)^(1/3)-1 -> 8.6249352 | C16: =(C14/B4)^(1/3)-1 -> 10.0178 | D16: =(D14/B4)^(1/3)-1 -> 11.612233

Sheet 08 · Marketing Plan
A1: MARKETING CAMPAIGN PLAN · GCC-focused, organic-first
A3: PHASE 1 — PRE-LAUNCH (Months 1-3) · $500 total
A4: Founder LinkedIn daily posts | B4: $0 | C4: Build in public, attract design partners
A5: Waitlist landing page | B5: $0 | C5: Lead capture, email list
A6: 20 design partner interviews | B6: $100 | C6: Small perks, coffee credits
A7: SEO foundation (10 pillar articles) | B7: $400 | C7: Arabic content writer
A9: PHASE 2 — LAUNCH (Months 4-6) · $2,000 total
A10: Product Hunt launch | B10: $0 | C10: Organic, top 5 of day target
A11: Hacker News Show HN | B11: $0 | C11: Founder-led post
A12: Reddit r/sales, r/saas (organic) | B12: $0 | C12: Community engagement
A13: LinkedIn MENA sponsored | B13: $1,200 | C13: GCC decision-makers, 2-3 months
A14: Google Ads (Arabic CRM keywords) | B14: $600 | C14: 2-3 months experimental
A15: YouTube demo videos (DIY) | B15: $200 | C15: Simple screen recordings + editing
A17: PHASE 3 — SCALE (Months 7-12) · $3,700 total
A18: Arabic content marketing (16 articles) | B18: $1,200 | C18: $75/article, SEO-optimized
A19: LinkedIn MENA ads continued | B19: $1,200 | C19: Retargeting + lookalikes
A20: LEAP / Biban event (shared booth) | B20: $750 | C20: GCC founder networking
A21: Affiliate/referral rewards | B21: $350 | C21: 20% commission structure
A22: Webinar series (monthly) | B22: $0 | C22: Founder-led, free tools
A23: Case studies from first 50 customers | B23: $200 | C23: Design + copy assistance
A26: TOTAL Y1 MARKETING | B26: $6,200
A28: EXPECTED CAC BY CHANNEL
A29: Organic / SEO / LinkedIn personal brand | B29: $5 | C29: Primary driver, free
A30: Product Hunt / community launch | B30: $15 | C30: One-time burst
A31: LinkedIn Ads (targeted) | B31: $80 | C31: Mid-market GCC
A32: Google Ads (keyword-targeted) | B32: $50 | C32: Intent-driven traffic
A33: Referral / affiliate | B33: $20 | C33: 20% rev share
A34: Event / LEAP / Biban | B34: $100 | C34: Relationship-driven, high ACV
A35: BLENDED CAC TARGET | B35: $5 | C35: Heavy organic skew

Sheet 09 · Reliability Stack
A1: RELIABILITY, UPTIME & DISASTER RECOVERY STACK
A2: CRM is mission-critical — target 99.9% uptime (max ~8.76 hrs downtime/yr)
A4: REDUNDANCY & AVAILABILITY
A5: Multi-AZ AWS deployment (3 AZs in me-south-1) | B5: Included | C5: High availability, no single point of failure
A6: PostgreSQL RDS Multi-AZ failover | B6: Included | C6: Automatic failover in <60 seconds
A7: Read replicas for query load | B7: Included | C7: Scales read performance
A8: Cross-region DR (eu-central-1 Frankfurt) | B8: $600/yr | C8: Disaster recovery backup region
A9: 99.9% uptime SLA target | B9: N/A | C9: Max 8.76 hrs downtime/year
A11: MONITORING & ALERTING
A12: Datadog APM | B12: $1,200/yr | C12: Real-time performance, DB queries, API latency
A13: Sentry error tracking | B13: $312/yr | C13: Instant exception alerts to Slack
A14: PagerDuty on-call | B14: $240/yr | C14: Alerts founder + devs within 60 seconds
A15: UptimeRobot external checks | B15: $84/yr | C15: Global uptime from 10 locations
A16: AWS CloudWatch | B16: Included | C16: Infrastructure metrics, auto-scaling triggers
A18: SECURITY & DDOS PROTECTION
A19: Cloudflare Pro | B19: $240/yr | C19: DDoS, WAF, CDN, bot detection
A20: AWS Shield Standard | B20: Free | C20: Network-layer DDoS protection
A21: Rate limiting (API gateway) | B21: Included | C21: Prevents abuse
A22: Daily automated backups | B22: $360/yr | C22: AWS Backup, 35-day retention
A23: Encryption at rest (AES-256) | B23: Included | C23: RDS + S3 encryption
A24: Encryption in transit (TLS 1.3) | B24: Included | C24: All API + web traffic
A26: DEPLOYMENT SAFETY
A27: Blue-green deployments | B27: Included | C27: Zero-downtime releases
A28: Feature flags (LaunchDarkly free) | B28: Free | C28: Instant rollback capability
A29: CI/CD (GitHub Actions) | B29: Free (public) / cheap | C29: Automated testing before deploy
A30: Staging environment | B30: $600/yr | C30: Mirrors production, catches bugs
A31: Backward-compatible schema migrations | B31: N/A | C31: Discipline, not cost
A33: INCIDENT RESPONSE
A34: Status page (Instatus free tier) | B34: Free | C34: Customer transparency during incidents
A35: Runbook documentation | B35: N/A | C35: Common incident playbooks
A36: Post-mortem process | B36: N/A | C36: Learn from every outage
A37: Customer comms within 15 min of incident | B37: SLA | C37: Professional trust builder
